#### 异常

1，封装错误信息的对象

2，错误信息：类型、提示消息、行号

#### 异常处理

1，使用返回值状态标识异常

- 返回值本身不能解释是否代表一个异常情况的发生
- 返回值本身不能解释一个异常的具体情况

2，异常处理机制

（1）程序从异常处跳出，抛出异常

（2）Java虚拟机寻找和try关键字匹配的catch块

（3）如果找到，交给catch块中的代码处理，然后继续往下执行程序

（4）找不到，执行finally代码块，调用当前线程的ThreadGroup的uncaughtException方法，然后终止当前线程

3，异常的捕获和处理

（1）Throwable类：子类：Exception和Error

- Exception：由于网络故障、文件损坏、设备错误、用户输入非法等情况导致的异常
- Error：表示Java运行时环境出现的错误，例如JVM内存资源耗尽

（2）try-catch

- try{...}语句指定一次捕获并处理异常的范围

- catch语句分别对不同的异常做相应的处理

- 多个catch捕获的异常类型由上至下的顺序是子类到父类


（3）finally的作用

- finally语句为异常处理提供一个统一的出口

- 无论是否抛出异常，finally所指定的代码都要被执行

- 通常在finally语句中可以进行资源的释放工作

（4）实例：try-catch,finally

```java
public static void main(String[] args) { 
    while(true){
        try{//异常捕获从try开始
            f();
            break;
        }catch (ArrayIndexOutOfBoundsException e){//用非法索引访问数组时抛出的异常
            System.out.println("输入两个！不是一个！");//输入一个下标1位置null抛出异常
        }catch(ArithmeticException e){//出现异常的运算条件时，抛出此异常
            System.out.println("不能除0！");
        }catch (Exception e){//异常(父类型)
            //先列出其他可能出现的子类型异常
            //再列出父类型，以防出现其他未知的错误
            System.out.println("出错，请重试！");
        }finally {//不管出错还是不出错都会执行
            System.out.println("----------------");
        }//异常捕获到这里finally{}结束
    }
}
private static void f() {
    System.out.println("输入逗号隔开的两个整数");
    String s=new Scanner(System.in).nextLine();
    String[]a=s.split(",");
    int n1=Integer.parseInt(a[0]);
    int n2=Integer.parseInt(a[1]);
    int r=n1/n2;//除0结果超出int范围
    System.out.println(r);
    //"532,53" is 10 
    //"345"    is 输入两个！不是一个！
    //"a,5"    is 出错，请重试！
    //"23,0"   is 不能除0！
    //"10 2"   is 出错，请重试！
}
```

（5）throw关键字

- 手动抛出指定的异常对象
- 类比成return（结束方法且将数据返回给调用方）

```java
//此例只是帮助理解：throw手动抛出（异常的/非默认的）异常
System.out.println("输入整数求和:");
int a=new Scanner(System.in).nextInt();
int b=new Scanner(System.in).nextInt();
try{
	if(a==0||b==0){//正常情况下0参与加法运算是不会出现异常的
        //这里手动抛出这个异常的异常
		ArithmeticException e=new ArithmeticException("/ by zero");
		throw e;
	}
	int r=a+b;
	System.out.println(r);
}catch(ArithmeticException e){
	System.out.println("此处规定不能输入0进行运算");
	e.printStackTrace();//打印完整异常
}
//如果输入a=1,b=0
/*结果：
此处规定不能输入0进行运算
java.lang.ArithmeticException: / by zero
*/
```

（6）throws关键字：声明处理异常的方法将会被抛出

子类重写throws方法：

- 可不处理异常

- 可仅throws父类中声明的部分异常

- 可throws父类方法中抛出异常的子类异常

- 不可throws额外的异常

- 不可throws父类方法中抛出异常的父类异常

```java
void f()throws Exception,ArithmeticException,
        ArrayIndexOutOfBoundsException {
}
```

（7）catch和throws

- Java语法，强制开发者事先考虑异常如何处理
- 异常处理两种方式，必须二选一：catch和throws
- 经验少时，不知道该在什么位置捕获处理，应该选择throws

```java
//不知道怎么处理时用throws Exception
//此时没有catch(Exception e)
public static void main(String[] args)throws Exception {
	FileWriter out = new FileWriter("k:/123.txt");
}//无法创建文件时: 打印显示：
//java.io.FileNotFoundException: k:\123.txt (系统找不到指定的路径。)
```

```java
//知道怎么处理时（完整版）
public static void main(String[] args)throws IOException {
    try{
        FileWriter out = new FileWriter("k:/123.txt");
    }catch (IOException e){
        System.out.println("无法创建文件，请检查文件路径");
    }//无法创建文件时
}    //打印显示：无法创建文件，请检查文件路径

//缺省版（缺省throws IOException）
public static void main(String[] args) {
	try{
		FileWriter out = new FileWriter("k:/123.txt");
	}catch (IOException e){
		System.out.println("无法创建文件，请检查文件路径");
	}
 }
```



#### Java异常API

1，Java异常：

- 可检测异常：编译器强制执行处理或声明规则，不捕捉这个异常不允许编译

- 非检测异常：不受编译器检查与处理或声明规则的限制


2，RuntimeException类：非检测异常

Java应用程序中会频繁出现JVM操作引起的运行时异常，因此他们不受编译器检查与处理或声明规则的限制

3，常见RuntimeException：

- illegalArgumentException：向方法传递了一个不合法或不正确的参数的异常
- NullPointerException：应用程序试图在需要对象的地方使用null时的异常

- ArrayIndexOutOfBoundsExceptin：使用的数组下标超出数组允许范围的异常

- IndexOutOfBoundsException：索引下标超出范围的异常

- ClassCastException：试图将对象强制转换为不是实例的子类的异常

- NumberFormatException：无法将字符串转换成适当格式的一种数值类型的异常

- ArithmeticException：出现异常的运算条件的异常

- ClassNotFoundException：无法找到指定的类的异常


4，Exception常用API：

（1）printStackTrace：跟踪异常事件发生时执行堆栈内容

- 该方法定义为：-void printStackTrace()

- try{...}catch(Exception e){e.printStackTrace();}//输出执行堆栈信息


（2）getMessage：得到有关异常事件的信息

- 该方法定义为：-String getMessage()
- try{...}catch(Exception e){System.out.println(e.getMessage());}


（3）getCause：

- Throwable getCause()：获取该异常出现的原因

5，异常包装：

（1）捕获的异常，包装成另一种类型，再抛出

（2）使用场景：

- 不能抛出的异常类型，包装成能抛出的类型，再抛
- 异常简化，把多种类型异常，简化成一种
- 子类重写方法时，异常管道不能比父类方法多

（3）实例：

```java
public static void main(String[] args) {
    try {
        f();
    }catch (Exception e){//异常包装 Exception类型的异常e
        throw new IllegalArgumentException(e);
        //根据指定的原因和的详细消息构造一个新异常
        //新异常是Exception范围内的具体的某种异常
        //IllegalArgumentException 不合法的数据异常 的包装器
    }
}
private static void f(){
    System.out.println("输入逗号隔开的两个整数:");
    String s=new Scanner(System.in).nextLine();
    String[]n=s.split(",");
    int a=Integer.parseInt(n[0]);
    int b=Integer.parseInt(n[1]);
    int r=a/b;//if b is 0; then r=Infinity;is 超出int范围
    System.out.println(r);
}
//"532,53" is 10 
//"345"    is Caused by: java.lang.ArrayIndexOutOfBoundsException: 1
//"a,5"    is Caused by: java.lang.NumberFormatException: For input string: "a"
//"23,0"   is Caused by: java.lang.ArithmeticException: / by zero
//"10 2"   is Caused by: java.lang.NumberFormatException: For input string: "10 2"
```

6，自定义Exception

（1）更加精准的捕获和处理异常，以呈现更好的用户体验

（2）创建自定义异常类：

- class 自定义异常类名  extends Exception{...}
- 生成继承的父类相应的构造方法


（3）实例：

```java
//自定义用户名异常
/*
- 起一个合适的类名
- 选一个合适的父类
- 添加合适的构造方法
*/
public class UsernameNotFoundException extends Exception {
    public UsernameNotFoundException(){
        super();
    }
    public UsernameNotFoundException(String message,Throwable cause,
                                     boolean enableSuppression,
                                     boolean writableStackTrace){
        super(message, cause, enableSuppression, writableStackTrace);
    }
    public UsernameNotFoundException(String message,Throwable cause){
        super(message, cause);
    }
    public UsernameNotFoundException(String message){
        super(message);
    }
    public UsernameNotFoundException(Throwable cause){
        super(cause);
    }
}
```

```java
//自定义密码异常
public class WrongPasswordException extends Exception{
    public WrongPasswordException(){
        super();
    }
    public WrongPasswordException(String message, Throwable cause,
                                  boolean enableSuppression,
                                  boolean writableStackTrace){
        super(message, cause, enableSuppression, writableStackTrace);
    }
    public WrongPasswordException(String message, Throwable cause){
        super(message, cause);
    }
    public WrongPasswordException(String message){
        super(message);
    }
    public WrongPasswordException(Throwable cause){
        super(cause);
    }
}
```

```java
//自定义异常的测试
public static void main(String[] args) {
    f();
}
private static void f() {
    System.out.print("用户名：");
    String n=new Scanner(System.in).nextLine();
    System.out.print("密码：");
    String p=new Scanner(System.in).nextLine();
    try{
        login(n,p);
        System.out.println("欢迎登陆");
    }catch(UsernameNotFoundException e){
        System.out.println("用户名错误");
    }catch (WrongPasswordException e){
        System.out.println("密码错误");
    }
}
private static void login(String n, String p) throws UsernameNotFoundException, WrongPasswordException {
    if(!"Java".equals(n)){
        throw new UsernameNotFoundException();
    }
    if(!"123456".equals(p)){
        throw new WrongPasswordException();
    }
}
```

















